Model: "sequential"
_________________________________________________________________
 Layer (type)                Output Shape              Param #
=================================================================
 conv2d (Conv2D)             (None, 254, 254, 8)       224
 conv2d_1 (Conv2D)           (None, 252, 252, 16)      1168
 max_pooling2d (MaxPooling2D  (None, 126, 126, 16)     0
 )
 flatten (Flatten)           (None, 254016)            0
 dense (Dense)               (None, 128)               32514176
 dense_1 (Dense)             (None, 64)                8256
 dense_2 (Dense)             (None, 5)                 325
=================================================================
Total params: 32,524,149
Trainable params: 32,524,149
Non-trainable params: 0
_________________________________________________________________
Epoch 1/10
Traceback (most recent call last):
  File "/Users/rocker/miniforge3/envs/dl-lab-22w-team06/lib/python3.8/site-packages/keras/utils/traceback_utils.py", line 70, in error_handler
    raise e.with_traceback(filtered_tb) from None
  File "/var/folders/b5/t7l_lrfd02l7d8_1f754tz0h0000gn/T/__autograph_generated_file0yth0o45.py", line 15, in tf__train_function
    retval_ = ag__.converted_call(ag__.ld(step_function), (ag__.ld(self), ag__.ld(iterator)), None, fscope)
ValueError: in user code:
    File "/Users/rocker/miniforge3/envs/dl-lab-22w-team06/lib/python3.8/site-packages/keras/engine/training.py", line 1160, in train_function  *
        return step_function(self, iterator)
    File "/Users/rocker/miniforge3/envs/dl-lab-22w-team06/lib/python3.8/site-packages/keras/engine/training.py", line 1146, in step_function  **
        outputs = model.distribute_strategy.run(run_step, args=(data,))
    File "/Users/rocker/miniforge3/envs/dl-lab-22w-team06/lib/python3.8/site-packages/keras/engine/training.py", line 1135, in run_step  **
        outputs = model.train_step(data)
    File "/Users/rocker/miniforge3/envs/dl-lab-22w-team06/lib/python3.8/site-packages/keras/engine/training.py", line 993, in train_step
        y_pred = self(x, training=True)
    File "/Users/rocker/miniforge3/envs/dl-lab-22w-team06/lib/python3.8/site-packages/keras/utils/traceback_utils.py", line 70, in error_handler
        raise e.with_traceback(filtered_tb) from None
    File "/Users/rocker/miniforge3/envs/dl-lab-22w-team06/lib/python3.8/site-packages/keras/engine/input_spec.py", line 295, in assert_input_compatibility
        raise ValueError(
    ValueError: Input 0 of layer "sequential" is incompatible with the layer: expected shape=(None, 256, 256, 3), found shape=(256, 256, 3)